< POST /restore/ HTTP/1.1
< Host: 127.0.0.1:8089
< User-Agent: python-requests/2.25.1
< Accept-Encoding: gzip, deflate
< Accept: */*
< Connection: keep-alive
< Content-Length: 111
< Content-Type: application/json
< 
< {"backup_id": 2147483648, "name": "aSUyfcpFyygkRSHjklpZLGxwXQdjbQVXpoTHZvjcxPScqRIbWXA", "timeout": 1636068137}
> HTTP/1.1 422 Unprocessable Entity
> Date: Wed, 14 Apr 2021 15:51:53 GMT
> Server: Apache/2.4.38 (Debian)
> X-Powered-By: PHP/8.0.3
> Cache-Control: no-cache, private
> Content-Length: 52
> Keep-Alive: timeout=5, max=100
> Connection: Keep-Alive
> Content-Type: application/json
> 
{"backup_id":["The selected backup id is invalid."]}